Workbook
Name NumberOfTeams: 'Team and Program Information'!$A$5
Name AwardListLookup: 'Team and Program Information'!$A$11:$A$20
Name NumberofTeamsAdvancing: 'Team and Program Information'!$A$8

Sheet Instructions
W1: DESIGNED FOR USE IN MICROSOFT EXCEL. SOME FUNCTIONALITY MAY BE LOST IN OTHER APPLICATIONS.
D4: 1. | E4: Open the 'Team and Program Information' page. Enter the team numbers and the team names. Also, the number of teams in this event as well as the number of teams advancing from this event in the box on the left. This information will show in the other sheets.
F5: You may notice that the team names do not appear on the 'Robot Game Scores' page - don’t worry, some events use an import for this page, you can still enter the scores manually and the data will still populate the results and ranking list. Columns C-L in 'Core Values Input' are intentially hidden and no data should be typed in those cells.
D6: 2. | E6: Many columns in the various tables have formulas. Please use caution to not accidentally edit or delete the formulas.
D7: 3. | E7: Collect the rubric scores from the judges and the robot game scores (including Gracious Professionalism® scores) from the referees throughout the event and enter the data into the corresponding sheets of this workbook.
F8: Core Values scores, except Gracious Professionalism scores from the robot game, are populated automatically from the other rubric scores - no score information should be added to columns C-L on the 'Core Values Input' page.
D9: 4. | E9: When all the data has been inputted, go the 'Results and Rankings' page to view all of the information in one place.
D10: 5. | E10: You are now ready to allocate your awards based on your rankings using the 'Awards and Allocations' document in the judging toolkit.
B12: Useful Tips: | F12: If you are copying data into the Input pages please remember to use the 'Paste Values' or 'Use Destination Formatting' option. | O12: You can sort your data by a specific column by clicking on the small arrow in the column header box and selecting 'sort smallest to largest' or 'A to Z'. | X12: As you work with the OJS you should save your spreadsheet regularly in case of IT issues. | AE12: If your event uses more than 3 official robot game matches, you can unhide columns G-H, using the plus (+) button above them, in 'Robot Game Scores' and columns P-Q in 'Core Values Input' for Gracious Professionalism scores.
F14: (This stops the formatting and formulae being overwritten) | AE14: If referees hand in printed scoresheets, robot game scores will need to be calclulated using the 'Official Scoring Calculator' tool (online).

Sheet Team and Program Information
A1: Version | C1: FIRST® LEGO® League Challenge Official Judging Spreadsheet
A2: UNEARTHED | B2: Row | C2: Team Number | D2: Team Name | E2: Coach | F2: Pod Number
B3: 1
A4: Number of Teams | B4: 2
A5: =COUNTA('Team and Program Information'!$C$3:$C$202) -> 0 | B5: 3
B6: 4
A7: Number of Teams Advancing | B7: 5
A8: 1 | B8: 6
B9: 7
A10: Award Lookup List | B10: 8
A11: Champion's | B11: 9
A12: Core Values | B12: 10
A13: Innovation Project | B13: 11
A14: Robot Design | B14: 12
A15: Engineering Excellence | B15: 13
A16: Breakthrough | B16: 14
A17: Rising All-Star | B17: 15
A18: Motivate | B18: 16
B19: 17
B20: 18
B21: 19
B22: 20
B23: 21
B24: 22
B25: 23
B26: 24
B27: 25
B28: 26
B29: 27
B30: 28
... B202: 200

Sheet Results and Rankings
A1: Team Information | C1: Robot Game | J1: Judging | M1: Overall | R1: Awards & Advancement | U1: Testing Items (Info Only) | Z1: Comments
A2: Team Number | B2: Team Name | C2: Robot Game Score 1 | D2: Robot Game Score 2 | E2: Robot Game Score 3 | F2: Robot Game Score 4 | G2: Robot Game Score 5 | H2: Max Robot Game Score | I2: Robot Game Rank | J2: Core Values Rank | K2: Innovation Project Rank | L2: Robot Design Rank | M2: Champion's Score | N2: Champion's Rank | O2: Breakthrough | P2: Rising All-Star | Q2: Motivate | R2: Award | S2: Award Place | T2: Advance? | U2: Core Values Score | V2: Innovattion Project Score | W2: Robot Design Score | X2: Overall Score - Geometric Mean | Y2: Overall Ranking - Geometric Mean | Z2: Comments
A3: {=XLOOKUP(1,'Team and Program Information'!$B$3:$B$202,'Team and Program Information'!$C$3:$C$202,"ERROR",0)} | B3: {=XLOOKUP('Results and Rankings'!$A3,'Team and Program Information'!$C$3:$C$202,'Team and Program Information'!$D$3:$D$202,"",0,)} -> #VALUE! | C3: {=IF('Results and Rankings'!$A3="","",XLOOKUP('Results and Rankings'!$A3,'Robot Game Scores'!$B$2:$B$201,'Robot Game Scores'!$D$2:$D$201,0,0,))} | D3: {=IF('Results and Rankings'!$A3="","",XLOOKUP('Results and Rankings'!$A3,'Robot Game Scores'!$B$2:$B$201,'Robot Game Scores'!$E$2:$E$201,0,0,))} | E3: {=IF('Results and Rankings'!$A3="","",XLOOKUP('Results and Rankings'!$A3,'Robot Game Scores'!$B$2:$B$201,'Robot Game Scores'!$F$2:$F$201,0,0,))} | F3: {=IF('Results and Rankings'!$A3="","",XLOOKUP('Results and Rankings'!$A3,'Robot Game Scores'!$B$2:$B$201,'Robot Game Scores'!$G$2:$G$201,0,0,))} | G3: {=IF('Results and Rankings'!$A3="","",XLOOKUP('Results and Rankings'!$A3,'Robot Game Scores'!$B$2:$B$201,'Robot Game Scores'!$H$2:$H$201,0,0,))} | H3: =IF('Results and Rankings'!$A3="","",IF(ISNA(LARGE('Results and Rankings'!$C3:$G3,1)+0.0001*LARGE('Results and Rankings'!$C3:$G3,2)+0.0000001*LARGE('Results and Rankings'!$C3:$G3,3)+1E-11*LARGE('Results and Rankings'!$C3:$G3,4)+1E-14*LARGE('Results and Rankings'!$C3:$G3,5)),0,LARGE('Results and Rankings'!$C3:$G3,1)+0.0001*LARGE('Results and Rankings'!$C3:$G3,2)+0.0000001*LARGE('Results and Rankings'!$C3:$G3,3)+1E-11*LARGE('Results and Rankings'!$C3:$G3,4)+1E-14*LARGE('Results and Rankings'!$C3:$G3,5))) | I3: =IF('Results and Rankings'!$A3="","",_xlfn.RANK.EQ('Results and Rankings'!$H3,'Results and Rankings'!$H$3:$H$202)) | J3: {=IF('Results and Rankings'!$A3="","",XLOOKUP('Results and Rankings'!$A3,'Core Values Input'!$A$2:$A$201,'Core Values Input'!$V$2:$V$201,NumberOfTeams+1,0,))} | K3: {=IF('Results and Rankings'!$A3="","",XLOOKUP('Results and Rankings'!$A3,'Innovation Project Input'!$A$2:$A$201,'Innovation Project Input'!$N$2:$N$201,NumberOfTeams+1,0,))} | L3: {=IF('Results and Rankings'!$A3="","",XLOOKUP('Results and Rankings'!$A3,'Robot Design Input'!$A$2:$A$201,'Robot Design Input'!$N$2:$N$201,NumberOfTeams+1,0,))} | M3: =IF('Results and Rankings'!$A3="","",IF('Results and Rankings'!$J3="",NumberOfTeams+1,'Results and Rankings'!$J3) + IF('Results and Rankings'!$K3="",NumberOfTeams+1,'Results and Rankings'!$K3) + IF('Results and Rankings'!$L3="",NumberOfTeams+1,'Results and Rankings'!$L3) + 'Results and Rankings'!$I3) | N3: =IF('Results and Rankings'!$A3="","",IF(M3,RANK(M3,M$3:M$202,1)-COUNTIF(M$3:M$202,0),NumberOfTeams+1)) | O3: {=XLOOKUP('Results and Rankings'!$A3,'Core Values Input'!$A$2:$A$201,'Core Values Input'!$W$2:$W$201,0,0,)} -> #VALUE! | P3: {=XLOOKUP('Results and Rankings'!$A3,'Core Values Input'!$A$2:$A$201,'Core Values Input'!$X$2:$X$201,0,0,)} -> #VALUE! | Q3: {=XLOOKUP('Results and Rankings'!$A3,'Core Values Input'!$A$2:$A$201,'Core Values Input'!$Y$2:$Y$201,0,0,)} -> #VALUE! | U3: {=XLOOKUP('Results and Rankings'!$A3,'Core Values Input'!$A$2:$A$201,'Core Values Input'!$U$2:$U$201,0,0,)} -> #VALUE! | V3: {=XLOOKUP('Results and Rankings'!$A3,'Innovation Project Input'!$A$2:$A$201,'Innovation Project Input'!$M$2:$M$201,0,0,)} -> #VALUE! | W3: {=XLOOKUP('Results and Rankings'!$A3,'Robot Design Input'!$A$2:$A$201,'Robot Design Input'!$M$2:$M$201,0,0,)} -> #VALUE! | X3: =IF(ISERR(GEOMEAN('Results and Rankings'!$H3,'Results and Rankings'!$U3,'Results and Rankings'!$V3,'Results and Rankings'!$W3)),0,GEOMEAN('Results and Rankings'!$H3,'Results and Rankings'!$U3,'Results and Rankings'!$V3,'Results and Rankings'!$W3)) -> 0 | Y3: =IF(X3,_xlfn.RANK.EQ(X3,X$3:X$110,0),NumberOfTeams) -> 0
A4: {=XLOOKUP(2,'Team and Program Information'!$B$3:$B$202,'Team and Program Information'!$C$3:$C$202,"ERROR",0)} | B4: {=XLOOKUP('Results and Rankings'!$A4,'Team and Program Information'!$C$3:$C$202,'Team and Program Information'!$D$3:$D$202,"",0,)} -> #VALUE! | C4: {=IF('Results and Rankings'!$A4="","",XLOOKUP('Results and Rankings'!$A4,'Robot Game Scores'!$B$2:$B$201,'Robot Game Scores'!$D$2:$D$201,0,0,))} | D4: {=IF('Results and Rankings'!$A4="","",XLOOKUP('Results and Rankings'!$A4,'Robot Game Scores'!$B$2:$B$201,'Robot Game Scores'!$E$2:$E$201,0,0,))} | E4: {=IF('Results and Rankings'!$A4="","",XLOOKUP('Results and Rankings'!$A4,'Robot Game Scores'!$B$2:$B$201,'Robot Game Scores'!$F$2:$F$201,0,0,))} | F4: {=IF('Results and Rankings'!$A4="","",XLOOKUP('Results and Rankings'!$A4,'Robot Game Scores'!$B$2:$B$201,'Robot Game Scores'!$G$2:$G$201,0,0,))} | G4: {=IF('Results and Rankings'!$A4="","",XLOOKUP('Results and Rankings'!$A4,'Robot Game Scores'!$B$2:$B$201,'Robot Game Scores'!$H$2:$H$201,0,0,))} | H4: =IF('Results and Rankings'!$A4="","",IF(ISNA(LARGE('Results and Rankings'!$C4:$G4,1)+0.0001*LARGE('Results and Rankings'!$C4:$G4,2)+0.0000001*LARGE('Results and Rankings'!$C4:$G4,3)+1E-11*LARGE('Results and Rankings'!$C4:$G4,4)+1E-14*LARGE('Results and Rankings'!$C4:$G4,5)),0,LARGE('Results and Rankings'!$C4:$G4,1)+0.0001*LARGE('Results and Rankings'!$C4:$G4,2)+0.0000001*LARGE('Results and Rankings'!$C4:$G4,3)+1E-11*LARGE('Results and Rankings'!$C4:$G4,4)+1E-14*LARGE('Results and Rankings'!$C4:$G4,5))) | I4: =IF('Results and Rankings'!$A4="","",_xlfn.RANK.EQ('Results and Rankings'!$H4,'Results and Rankings'!$H$3:$H$202)) | J4: {=IF('Results and Rankings'!$A4="","",XLOOKUP('Results and Rankings'!$A4,'Core Values Input'!$A$2:$A$201,'Core Values Input'!$V$2:$V$201,NumberOfTeams+1,0,))} | K4: {=IF('Results and Rankings'!$A4="","",XLOOKUP('Results and Rankings'!$A4,'Innovation Project Input'!$A$2:$A$201,'Innovation Project Input'!$N$2:$N$201,NumberOfTeams+1,0,))} | L4: {=IF('Results and Rankings'!$A4="","",XLOOKUP('Results and Rankings'!$A4,'Robot Design Input'!$A$2:$A$201,'Robot Design Input'!$N$2:$N$201,NumberOfTeams+1,0,))} | M4: =IF('Results and Rankings'!$A4="","",IF('Results and Rankings'!$J4="",NumberOfTeams+1,'Results and Rankings'!$J4) + IF('Results and Rankings'!$K4="",NumberOfTeams+1,'Results and Rankings'!$K4) + IF('Results and Rankings'!$L4="",NumberOfTeams+1,'Results and Rankings'!$L4) + 'Results and Rankings'!$I4) | N4: =IF('Results and Rankings'!$A4="","",IF(M4,RANK(M4,M$3:M$202,1)-COUNTIF(M$3:M$202,0),NumberOfTeams+1)) | O4: {=XLOOKUP('Results and Rankings'!$A4,'Core Values Input'!$A$2:$A$201,'Core Values Input'!$W$2:$W$201,0,0,)} -> #VALUE! | P4: {=XLOOKUP('Results and Rankings'!$A4,'Core Values Input'!$A$2:$A$201,'Core Values Input'!$X$2:$X$201,0,0,)} -> #VALUE! | Q4: {=XLOOKUP('Results and Rankings'!$A4,'Core Values Input'!$A$2:$A$201,'Core Values Input'!$Y$2:$Y$201,0,0,)} -> #VALUE! | U4: {=XLOOKUP('Results and Rankings'!$A4,'Core Values Input'!$A$2:$A$201,'Core Values Input'!$U$2:$U$201,0,0,)} -> #VALUE! | V4: {=XLOOKUP('Results and Rankings'!$A4,'Innovation Project Input'!$A$2:$A$201,'Innovation Project Input'!$M$2:$M$201,0,0,)} -> #VALUE! | W4: {=XLOOKUP('Results and Rankings'!$A4,'Robot Design Input'!$A$2:$A$201,'Robot Design Input'!$M$2:$M$201,0,0,)} -> #VALUE! | X4: =IF(ISERR(GEOMEAN('Results and Rankings'!$H4,'Results and Rankings'!$U4,'Results and Rankings'!$V4,'Results and Rankings'!$W4)),0,GEOMEAN('Results and Rankings'!$H4,'Results and Rankings'!$U4,'Results and Rankings'!$V4,'Results and Rankings'!$W4)) -> 0 | Y4: =IF(X4,_xlfn.RANK.EQ(X4,X$3:X$110,0),NumberOfTeams) -> 0
A5: {=XLOOKUP(3,'Team and Program Information'!$B$3:$B$202,'Team and Program Information'!$C$3:$C$202,"ERROR",0)} | B5: {=XLOOKUP('Results and Rankings'!$A5,'Team and Program Information'!$C$3:$C$202,'Team and Program Information'!$D$3:$D$202,"",0,)} -> #VALUE! | C5: {=IF('Results and Rankings'!$A5="","",XLOOKUP('Results and Rankings'!$A5,'Robot Game Scores'!$B$2:$B$201,'Robot Game Scores'!$D$2:$D$201,0,0,))} | D5: {=IF('Results and Rankings'!$A5="","",XLOOKUP('Results and Rankings'!$A5,'Robot Game Scores'!$B$2:$B$201,'Robot Game Scores'!$E$2:$E$201,0,0,))} | E5: {=IF('Results and Rankings'!$A5="","",XLOOKUP('Results and Rankings'!$A5,'Robot Game Scores'!$B$2:$B$201,'Robot Game Scores'!$F$2:$F$201,0,0,))} | F5: {=IF('Results and Rankings'!$A5="","",XLOOKUP('Results and Rankings'!$A5,'Robot Game Scores'!$B$2:$B$201,'Robot Game Scores'!$G$2:$G$201,0,0,))} | G5: {=IF('Results and Rankings'!$A5="","",XLOOKUP('Results and Rankings'!$A5,'Robot Game Scores'!$B$2:$B$201,'Robot Game Scores'!$H$2:$H$201,0,0,))} | H5: =IF('Results and Rankings'!$A5="","",IF(ISNA(LARGE('Results and Rankings'!$C5:$G5,1)+0.0001*LARGE('Results and Rankings'!$C5:$G5,2)+0.0000001*LARGE('Results and Rankings'!$C5:$G5,3)+1E-11*LARGE('Results and Rankings'!$C5:$G5,4)+1E-14*LARGE('Results and Rankings'!$C5:$G5,5)),0,LARGE('Results and Rankings'!$C5:$G5,1)+0.0001*LARGE('Results and Rankings'!$C5:$G5,2)+0.0000001*LARGE('Results and Rankings'!$C5:$G5,3)+1E-11*LARGE('Results and Rankings'!$C5:$G5,4)+1E-14*LARGE('Results and Rankings'!$C5:$G5,5))) | I5: =IF('Results and Rankings'!$A5="","",_xlfn.RANK.EQ('Results and Rankings'!$H5,'Results and Rankings'!$H$3:$H$202)) | J5: {=IF('Results and Rankings'!$A5="","",XLOOKUP('Results and Rankings'!$A5,'Core Values Input'!$A$2:$A$201,'Core Values Input'!$V$2:$V$201,NumberOfTeams+1,0,))} | K5: {=IF('Results and Rankings'!$A5="","",XLOOKUP('Results and Rankings'!$A5,'Innovation Project Input'!$A$2:$A$201,'Innovation Project Input'!$N$2:$N$201,NumberOfTeams+1,0,))} | L5: {=IF('Results and Rankings'!$A5="","",XLOOKUP('Results and Rankings'!$A5,'Robot Design Input'!$A$2:$A$201,'Robot Design Input'!$N$2:$N$201,NumberOfTeams+1,0,))} | M5: =IF('Results and Rankings'!$A5="","",IF('Results and Rankings'!$J5="",NumberOfTeams+1,'Results and Rankings'!$J5) + IF('Results and Rankings'!$K5="",NumberOfTeams+1,'Results and Rankings'!$K5) + IF('Results and Rankings'!$L5="",NumberOfTeams+1,'Results and Rankings'!$L5) + 'Results and Rankings'!$I5) | N5: =IF('Results and Rankings'!$A5="","",IF(M5,RANK(M5,M$3:M$202,1)-COUNTIF(M$3:M$202,0),NumberOfTeams+1)) | O5: {=XLOOKUP('Results and Rankings'!$A5,'Core Values Input'!$A$2:$A$201,'Core Values Input'!$W$2:$W$201,0,0,)} -> #VALUE! | P5: {=XLOOKUP('Results and Rankings'!$A5,'Core Values Input'!$A$2:$A$201,'Core Values Input'!$X$2:$X$201,0,0,)} -> #VALUE! | Q5: {=XLOOKUP('Results and Rankings'!$A5,'Core Values Input'!$A$2:$A$201,'Core Values Input'!$Y$2:$Y$201,0,0,)} -> #VALUE! | U5: {=XLOOKUP('Results and Rankings'!$A5,'Core Values Input'!$A$2:$A$201,'Core Values Input'!$U$2:$U$201,0,0,)} -> #VALUE! | V5: {=XLOOKUP('Results and Rankings'!$A5,'Innovation Project Input'!$A$2:$A$201,'Innovation Project Input'!$M$2:$M$201,0,0,)} -> #VALUE! | W5: {=XLOOKUP('Results and Rankings'!$A5,'Robot Design Input'!$A$2:$A$201,'Robot Design Input'!$M$2:$M$201,0,0,)} -> #VALUE! | X5: =IF(ISERR(GEOMEAN('Results and Rankings'!$H5,'Results and Rankings'!$U5,'Results and Rankings'!$V5,'Results and Rankings'!$W5)),0,GEOMEAN('Results and Rankings'!$H5,'Results and Rankings'!$U5,'Results and Rankings'!$V5,'Results and Rankings'!$W5)) -> 0 | Y5: =IF(X5,_xlfn.RANK.EQ(X5,X$3:X$110,0),NumberOfTeams) -> 0
A6: {=XLOOKUP(4,'Team and Program Information'!$B$3:$B$202,'Team and Program Information'!$C$3:$C$202,"ERROR",0)} | B6: {=XLOOKUP('Results and Rankings'!$A6,'Team and Program Information'!$C$3:$C$202,'Team and Program Information'!$D$3:$D$202,"",0,)} -> #VALUE! | C6: {=IF('Results and Rankings'!$A6="","",XLOOKUP('Results and Rankings'!$A6,'Robot Game Scores'!$B$2:$B$201,'Robot Game Scores'!$D$2:$D$201,0,0,))} | D6: {=IF('Results and Rankings'!$A6="","",XLOOKUP('Results and Rankings'!$A6,'Robot Game Scores'!$B$2:$B$201,'Robot Game Scores'!$E$2:$E$201,0,0,))} | E6: {=IF('Results and Rankings'!$A6="","",XLOOKUP('Results and Rankings'!$A6,'Robot Game Scores'!$B$2:$B$201,'Robot Game Scores'!$F$2:$F$201,0,0,))} | F6: {=IF('Results and Rankings'!$A6="","",XLOOKUP('Results and Rankings'!$A6,'Robot Game Scores'!$B$2:$B$201,'Robot Game Scores'!$G$2:$G$201,0,0,))} | G6: {=IF('Results and Rankings'!$A6="","",XLOOKUP('Results and Rankings'!$A6,'Robot Game Scores'!$B$2:$B$201,'Robot Game Scores'!$H$2:$H$201,0,0,))} | H6: =IF('Results and Rankings'!$A6="","",IF(ISNA(LARGE('Results and Rankings'!$C6:$G6,1)+0.0001*LARGE('Results and Rankings'!$C6:$G6,2)+0.0000001*LARGE('Results and Rankings'!$C6:$G6,3)+1E-11*LARGE('Results and Rankings'!$C6:$G6,4)+1E-14*LARGE('Results and Rankings'!$C6:$G6,5)),0,LARGE('Results and Rankings'!$C6:$G6,1)+0.0001*LARGE('Results and Rankings'!$C6:$G6,2)+0.0000001*LARGE('Results and Rankings'!$C6:$G6,3)+1E-11*LARGE('Results and Rankings'!$C6:$G6,4)+1E-14*LARGE('Results and Rankings'!$C6:$G6,5))) | I6: =IF('Results and Rankings'!$A6="","",_xlfn.RANK.EQ('Results and Rankings'!$H6,'Results and Rankings'!$H$3:$H$202)) | J6: {=IF('Results and Rankings'!$A6="","",XLOOKUP('Results and Rankings'!$A6,'Core Values Input'!$A$2:$A$201,'Core Values Input'!$V$2:$V$201,NumberOfTeams+1,0,))} | K6: {=IF('Results and Rankings'!$A6="","",XLOOKUP('Results and Rankings'!$A6,'Innovation Project Input'!$A$2:$A$201,'Innovation Project Input'!$N$2:$N$201,NumberOfTeams+1,0,))} | L6: {=IF('Results and Rankings'!$A6="","",XLOOKUP('Results and Rankings'!$A6,'Robot Design Input'!$A$2:$A$201,'Robot Design Input'!$N$2:$N$201,NumberOfTeams+1,0,))} | M6: =IF('Results and Rankings'!$A6="","",IF('Results and Rankings'!$J6="",NumberOfTeams+1,'Results and Rankings'!$J6) + IF('Results and Rankings'!$K6="",NumberOfTeams+1,'Results and Rankings'!$K6) + IF('Results and Rankings'!$L6="",NumberOfTeams+1,'Results and Rankings'!$L6) + 'Results and Rankings'!$I6) | N6: =IF('Results and Rankings'!$A6="","",IF(M6,RANK(M6,M$3:M$202,1)-COUNTIF(M$3:M$202,0),NumberOfTeams+1)) | O6: {=XLOOKUP('Results and Rankings'!$A6,'Core Values Input'!$A$2:$A$201,'Core Values Input'!$W$2:$W$201,0,0,)} -> #VALUE! | P6: {=XLOOKUP('Results and Rankings'!$A6,'Core Values Input'!$A$2:$A$201,'Core Values Input'!$X$2:$X$201,0,0,)} -> #VALUE! | Q6: {=XLOOKUP('Results and Rankings'!$A6,'Core Values Input'!$A$2:$A$201,'Core Values Input'!$Y$2:$Y$201,0,0,)} -> #VALUE! | U6: {=XLOOKUP('Results and Rankings'!$A6,'Core Values Input'!$A$2:$A$201,'Core Values Input'!$U$2:$U$201,0,0,)} -> #VALUE! | V6: {=XLOOKUP('Results and Rankings'!$A6,'Innovation Project Input'!$A$2:$A$201,'Innovation Project Input'!$M$2:$M$201,0,0,)} -> #VALUE! | W6: {=XLOOKUP('Results and Rankings'!$A6,'Robot Design Input'!$A$2:$A$201,'Robot Design Input'!$M$2:$M$201,0,0,)} -> #VALUE! | X6: =IF(ISERR(GEOMEAN('Results and Rankings'!$H6,'Results and Rankings'!$U6,'Results and Rankings'!$V6,'Results and Rankings'!$W6)),0,GEOMEAN('Results and Rankings'!$H6,'Results and Rankings'!$U6,'Results and Rankings'!$V6,'Results and Rankings'!$W6)) -> 0 | Y6: =IF(X6,_xlfn.RANK.EQ(X6,X$3:X$110,0),NumberOfTeams) -> 0
A7: {=XLOOKUP(5,'Team and Program Information'!$B$3:$B$202,'Team and Program Information'!$C$3:$C$202,"ERROR",0)} | B7: {=XLOOKUP('Results and Rankings'!$A7,'Team and Program Information'!$C$3:$C$202,'Team and Program Information'!$D$3:$D$202,"",0,)} -> #VALUE! | C7: {=IF('Results and Rankings'!$A7="","",XLOOKUP('Results and Rankings'!$A7,'Robot Game Scores'!$B$2:$B$201,'Robot Game Scores'!$D$2:$D$201,0,0,))} | D7: {=IF('Results and Rankings'!$A7="","",XLOOKUP('Results and Rankings'!$A7,'Robot Game Scores'!$B$2:$B$201,'Robot Game Scores'!$E$2:$E$201,0,0,))} | E7: {=IF('Results and Rankings'!$A7="","",XLOOKUP('Results and Rankings'!$A7,'Robot Game Scores'!$B$2:$B$201,'Robot Game Scores'!$F$2:$F$201,0,0,))} | F7: {=IF('Results and Rankings'!$A7="","",XLOOKUP('Results and Rankings'!$A7,'Robot Game Scores'!$B$2:$B$201,'Robot Game Scores'!$G$2:$G$201,0,0,))} | G7: {=IF('Results and Rankings'!$A7="","",XLOOKUP('Results and Rankings'!$A7,'Robot Game Scores'!$B$2:$B$201,'Robot Game Scores'!$H$2:$H$201,0,0,))} | H7: =IF('Results and Rankings'!$A7="","",IF(ISNA(LARGE('Results and Rankings'!$C7:$G7,1)+0.0001*LARGE('Results and Rankings'!$C7:$G7,2)+0.0000001*LARGE('Results and Rankings'!$C7:$G7,3)+1E-11*LARGE('Results and Rankings'!$C7:$G7,4)+1E-14*LARGE('Results and Rankings'!$C7:$G7,5)),0,LARGE('Results and Rankings'!$C7:$G7,1)+0.0001*LARGE('Results and Rankings'!$C7:$G7,2)+0.0000001*LARGE('Results and Rankings'!$C7:$G7,3)+1E-11*LARGE('Results and Rankings'!$C7:$G7,4)+1E-14*LARGE('Results and Rankings'!$C7:$G7,5))) | I7: =IF('Results and Rankings'!$A7="","",_xlfn.RANK.EQ('Results and Rankings'!$H7,'Results and Rankings'!$H$3:$H$202)) | J7: {=IF('Results and Rankings'!$A7="","",XLOOKUP('Results and Rankings'!$A7,'Core Values Input'!$A$2:$A$201,'Core Values Input'!$V$2:$V$201,NumberOfTeams+1,0,))} | K7: {=IF('Results and Rankings'!$A7="","",XLOOKUP('Results and Rankings'!$A7,'Innovation Project Input'!$A$2:$A$201,'Innovation Project Input'!$N$2:$N$201,NumberOfTeams+1,0,))} | L7: {=IF('Results and Rankings'!$A7="","",XLOOKUP('Results and Rankings'!$A7,'Robot Design Input'!$A$2:$A$201,'Robot Design Input'!$N$2:$N$201,NumberOfTeams+1,0,))} | M7: =IF('Results and Rankings'!$A7="","",IF('Results and Rankings'!$J7="",NumberOfTeams+1,'Results and Rankings'!$J7) + IF('Results and Rankings'!$K7="",NumberOfTeams+1,'Results and Rankings'!$K7) + IF('Results and Rankings'!$L7="",NumberOfTeams+1,'Results and Rankings'!$L7) + 'Results and Rankings'!$I7) | N7: =IF('Results and Rankings'!$A7="","",IF(M7,RANK(M7,M$3:M$202,1)-COUNTIF(M$3:M$202,0),NumberOfTeams+1)) | O7: {=XLOOKUP('Results and Rankings'!$A7,'Core Values Input'!$A$2:$A$201,'Core Values Input'!$W$2:$W$201,0,0,)} -> #VALUE! | P7: {=XLOOKUP('Results and Rankings'!$A7,'Core Values Input'!$A$2:$A$201,'Core Values Input'!$X$2:$X$201,0,0,)} -> #VALUE! | Q7: {=XLOOKUP('Results and Rankings'!$A7,'Core Values Input'!$A$2:$A$201,'Core Values Input'!$Y$2:$Y$201,0,0,)} -> #VALUE! | U7: {=XLOOKUP('Results and Rankings'!$A7,'Core Values Input'!$A$2:$A$201,'Core Values Input'!$U$2:$U$201,0,0,)} -> #VALUE! | V7: {=XLOOKUP('Results and Rankings'!$A7,'Innovation Project Input'!$A$2:$A$201,'Innovation Project Input'!$M$2:$M$201,0,0,)} -> #VALUE! | W7: {=XLOOKUP('Results and Rankings'!$A7,'Robot Design Input'!$A$2:$A$201,'Robot Design Input'!$M$2:$M$201,0,0,)} -> #VALUE! | X7: =IF(ISERR(GEOMEAN('Results and Rankings'!$H7,'Results and Rankings'!$U7,'Results and Rankings'!$V7,'Results and Rankings'!$W7)),0,GEOMEAN('Results and Rankings'!$H7,'Results and Rankings'!$U7,'Results and Rankings'!$V7,'Results and Rankings'!$W7)) -> 0 | Y7: =IF(X7,_xlfn.RANK.EQ(X7,X$3:X$110,0),NumberOfTeams) -> 0
A8: {=XLOOKUP(6,'Team and Program Information'!$B$3:$B$202,'Team and Program Information'!$C$3:$C$202,"ERROR",0)} | B8: {=XLOOKUP('Results and Rankings'!$A8,'Team and Program Information'!$C$3:$C$202,'Team and Program Information'!$D$3:$D$202,"",0,)} -> #VALUE! | C8: {=IF('Results and Rankings'!$A8="","",XLOOKUP('Results and Rankings'!$A8,'Robot Game Scores'!$B$2:$B$201,'Robot Game Scores'!$D$2:$D$201,0,0,))} | D8: {=IF('Results and Rankings'!$A8="","",XLOOKUP('Results and Rankings'!$A8,'Robot Game Scores'!$B$2:$B$201,'Robot Game Scores'!$E$2:$E$201,0,0,))} | E8: {=IF('Results and Rankings'!$A8="","",XLOOKUP('Results and Rankings'!$A8,'Robot Game Scores'!$B$2:$B$201,'Robot Game Scores'!$F$2:$F$201,0,0,))} | F8: {=IF('Results and Rankings'!$A8="","",XLOOKUP('Results and Rankings'!$A8,'Robot Game Scores'!$B$2:$B$201,'Robot Game Scores'!$G$2:$G$201,0,0,))} | G8: {=IF('Results and Rankings'!$A8="","",XLOOKUP('Results and Rankings'!$A8,'Robot Game Scores'!$B$2:$B$201,'Robot Game Scores'!$H$2:$H$201,0,0,))} | H8: =IF('Results and Rankings'!$A8="","",IF(ISNA(LARGE('Results and Rankings'!$C8:$G8,1)+0.0001*LARGE('Results and Rankings'!$C8:$G8,2)+0.0000001*LARGE('Results and Rankings'!$C8:$G8,3)+1E-11*LARGE('Results and Rankings'!$C8:$G8,4)+1E-14*LARGE('Results and Rankings'!$C8:$G8,5)),0,LARGE('Results and Rankings'!$C8:$G8,1)+0.0001*LARGE('Results and Rankings'!$C8:$G8,2)+0.0000001*LARGE('Results and Rankings'!$C8:$G8,3)+1E-11*LARGE('Results and Rankings'!$C8:$G8,4)+1E-14*LARGE('Results and Rankings'!$C8:$G8,5))) | I8: =IF('Results and Rankings'!$A8="","",_xlfn.RANK.EQ('Results and Rankings'!$H8,'Results and Rankings'!$H$3:$H$202)) | J8: {=IF('Results and Rankings'!$A8="","",XLOOKUP('Results and Rankings'!$A8,'Core Values Input'!$A$2:$A$201,'Core Values Input'!$V$2:$V$201,NumberOfTeams+1,0,))} | K8: {=IF('Results and Rankings'!$A8="","",XLOOKUP('Results and Rankings'!$A8,'Innovation Project Input'!$A$2:$A$201,'Innovation Project Input'!$N$2:$N$201,NumberOfTeams+1,0,))} | L8: {=IF('Results and Rankings'!$A8="","",XLOOKUP('Results and Rankings'!$A8,'Robot Design Input'!$A$2:$A$201,'Robot Design Input'!$N$2:$N$201,NumberOfTeams+1,0,))} | M8: =IF('Results and Rankings'!$A8="","",IF('Results and Rankings'!$J8="",NumberOfTeams+1,'Results and Rankings'!$J8) + IF('Results and Rankings'!$K8="",NumberOfTeams+1,'Results and Rankings'!$K8) + IF('Results and Rankings'!$L8="",NumberOfTeams+1,'Results and Rankings'!$L8) + 'Results and Rankings'!$I8) | N8: =IF('Results and Rankings'!$A8="","",IF(M8,RANK(M8,M$3:M$202,1)-COUNTIF(M$3:M$202,0),NumberOfTeams+1)) | O8: {=XLOOKUP('Results and Rankings'!$A8,'Core Values Input'!$A$2:$A$201,'Core Values Input'!$W$2:$W$201,0,0,)} -> #VALUE! | P8: {=XLOOKUP('Results and Rankings'!$A8,'Core Values Input'!$A$2:$A$201,'Core Values Input'!$X$2:$X$201,0,0,)} -> #VALUE! | Q8: {=XLOOKUP('Results and Rankings'!$A8,'Core Values Input'!$A$2:$A$201,'Core Values Input'!$Y$2:$Y$201,0,0,)} -> #VALUE! | U8: {=XLOOKUP('Results and Rankings'!$A8,'Core Values Input'!$A$2:$A$201,'Core Values Input'!$U$2:$U$201,0,0,)} -> #VALUE! | V8: {=XLOOKUP('Results and Rankings'!$A8,'Innovation Project Input'!$A$2:$A$201,'Innovation Project Input'!$M$2:$M$201,0,0,)} -> #VALUE! | W8: {=XLOOKUP('Results and Rankings'!$A8,'Robot Design Input'!$A$2:$A$201,'Robot Design Input'!$M$2:$M$201,0,0,)} -> #VALUE! | X8: =IF(ISERR(GEOMEAN('Results and Rankings'!$H8,'Results and Rankings'!$U8,'Results and Rankings'!$V8,'Results and Rankings'!$W8)),0,GEOMEAN('Results and Rankings'!$H8,'Results and Rankings'!$U8,'Results and Rankings'!$V8,'Results and Rankings'!$W8)) -> 0 | Y8: =IF(X8,_xlfn.RANK.EQ(X8,X$3:X$110,0),NumberOfTeams) -> 0
A9: {=XLOOKUP(7,'Team and Program Information'!$B$3:$B$202,'Team and Program Information'!$C$3:$C$202,"ERROR",0)} | B9: {=XLOOKUP('Results and Rankings'!$A9,'Team and Program Information'!$C$3:$C$202,'Team and Program Information'!$D$3:$D$202,"",0,)} -> #VALUE! | C9: {=IF('Results and Rankings'!$A9="","",XLOOKUP('Results and Rankings'!$A9,'Robot Game Scores'!$B$2:$B$201,'Robot Game Scores'!$D$2:$D$201,0,0,))} | D9: {=IF('Results and Rankings'!$A9="","",XLOOKUP('Results and Rankings'!$A9,'Robot Game Scores'!$B$2:$B$201,'Robot Game Scores'!$E$2:$E$201,0,0,))} | E9: {=IF('Results and Rankings'!$A9="","",XLOOKUP('Results and Rankings'!$A9,'Robot Game Scores'!$B$2:$B$201,'Robot Game Scores'!$F$2:$F$201,0,0,))} | F9: {=IF('Results and Rankings'!$A9="","",XLOOKUP('Results and Rankings'!$A9,'Robot Game Scores'!$B$2:$B$201,'Robot Game Scores'!$G$2:$G$201,0,0,))} | G9: {=IF('Results and Rankings'!$A9="","",XLOOKUP('Results and Rankings'!$A9,'Robot Game Scores'!$B$2:$B$201,'Robot Game Scores'!$H$2:$H$201,0,0,))} | H9: =IF('Results and Rankings'!$A9="","",IF(ISNA(LARGE('Results and Rankings'!$C9:$G9,1)+0.0001*LARGE('Results and Rankings'!$C9:$G9,2)+0.0000001*LARGE('Results and Rankings'!$C9:$G9,3)+1E-11*LARGE('Results and Rankings'!$C9:$G9,4)+1E-14*LARGE('Results and Rankings'!$C9:$G9,5)),0,LARGE('Results and Rankings'!$C9:$G9,1)+0.0001*LARGE('Results and Rankings'!$C9:$G9,2)+0.0000001*LARGE('Results and Rankings'!$C9:$G9,3)+1E-11*LARGE('Results and Rankings'!$C9:$G9,4)+1E-14*LARGE('Results and Rankings'!$C9:$G9,5))) | I9: =IF('Results and Rankings'!$A9="","",_xlfn.RANK.EQ('Results and Rankings'!$H9,'Results and Rankings'!$H$3:$H$202)) | J9: {=IF('Results and Rankings'!$A9="","",XLOOKUP('Results and Rankings'!$A9,'Core Values Input'!$A$2:$A$201,'Core Values Input'!$V$2:$V$201,NumberOfTeams+1,0,))} | K9: {=IF('Results and Rankings'!$A9="","",XLOOKUP('Results and Rankings'!$A9,'Innovation Project Input'!$A$2:$A$201,'Innovation Project Input'!$N$2:$N$201,NumberOfTeams+1,0,))} | L9: {=IF('Results and Rankings'!$A9="","",XLOOKUP('Results and Rankings'!$A9,'Robot Design Input'!$A$2:$A$201,'Robot Design Input'!$N$2:$N$201,NumberOfTeams+1,0,))} | M9: =IF('Results and Rankings'!$A9="","",IF('Results and Rankings'!$J9="",NumberOfTeams+1,'Results and Rankings'!$J9) + IF('Results and Rankings'!$K9="",NumberOfTeams+1,'Results and Rankings'!$K9) + IF('Results and Rankings'!$L9="",NumberOfTeams+1,'Results and Rankings'!$L9) + 'Results and Rankings'!$I9) | N9: =IF('Results and Rankings'!$A9="","",IF(M9,RANK(M9,M$3:M$202,1)-COUNTIF(M$3:M$202,0),NumberOfTeams+1)) | O9: {=XLOOKUP('Results and Rankings'!$A9,'Core Values Input'!$A$2:$A$201,'Core Values Input'!$W$2:$W$201,0,0,)} -> #VALUE! | P9: {=XLOOKUP('Results and Rankings'!$A9,'Core Values Input'!$A$2:$A$201,'Core Values Input'!$X$2:$X$201,0,0,)} -> #VALUE! | Q9: {=XLOOKUP('Results and Rankings'!$A9,'Core Values Input'!$A$2:$A$201,'Core Values Input'!$Y$2:$Y$201,0,0,)} -> #VALUE! | U9: {=XLOOKUP('Results and Rankings'!$A9,'Core Values Input'!$A$2:$A$201,'Core Values Input'!$U$2:$U$201,0,0,)} -> #VALUE! | V9: {=XLOOKUP('Results and Rankings'!$A9,'Innovation Project Input'!$A$2:$A$201,'Innovation Project Input'!$M$2:$M$201,0,0,)} -> #VALUE! | W9: {=XLOOKUP('Results and Rankings'!$A9,'Robot Design Input'!$A$2:$A$201,'Robot Design Input'!$M$2:$M$201,0,0,)} -> #VALUE! | X9: =IF(ISERR(GEOMEAN('Results and Rankings'!$H9,'Results and Rankings'!$U9,'Results and Rankings'!$V9,'Results and Rankings'!$W9)),0,GEOMEAN('Results and Rankings'!$H9,'Results and Rankings'!$U9,'Results and Rankings'!$V9,'Results and Rankings'!$W9)) -> 0 | Y9: =IF(X9,_xlfn.RANK.EQ(X9,X$3:X$110,0),NumberOfTeams) -> 0
A10: {=XLOOKUP(8,'Team and Program Information'!$B$3:$B$202,'Team and Program Information'!$C$3:$C$202,"ERROR",0)} | B10: {=XLOOKUP('Results and Rankings'!$A10,'Team and Program Information'!$C$3:$C$202,'Team and Program Information'!$D$3:$D$202,"",0,)} -> #VALUE! | C10: {=IF('Results and Rankings'!$A10="","",XLOOKUP('Results and Rankings'!$A10,'Robot Game Scores'!$B$2:$B$201,'Robot Game Scores'!$D$2:$D$201,0,0,))} | D10: {=IF('Results and Rankings'!$A10="","",XLOOKUP('Results and Rankings'!$A10,'Robot Game Scores'!$B$2:$B$201,'Robot Game Scores'!$E$2:$E$201,0,0,))} | E10: {=IF('Results and Rankings'!$A10="","",XLOOKUP('Results and Rankings'!$A10,'Robot Game Scores'!$B$2:$B$201,'Robot Game Scores'!$F$2:$F$201,0,0,))} | F10: {=IF('Results and Rankings'!$A10="","",XLOOKUP('Results and Rankings'!$A10,'Robot Game Scores'!$B$2:$B$201,'Robot Game Scores'!$G$2:$G$201,0,0,))} | G10: {=IF('Results and Rankings'!$A10="","",XLOOKUP('Results and Rankings'!$A10,'Robot Game Scores'!$B$2:$B$201,'Robot Game Scores'!$H$2:$H$201,0,0,))} | H10: =IF('Results and Rankings'!$A10="","",IF(ISNA(LARGE('Results and Rankings'!$C10:$G10,1)+0.0001*LARGE('Results and Rankings'!$C10:$G10,2)+0.0000001*LARGE('Results and Rankings'!$C10:$G10,3)+1E-11*LARGE('Results and Rankings'!$C10:$G10,4)+1E-14*LARGE('Results and Rankings'!$C10:$G10,5)),0,LARGE('Results and Rankings'!$C10:$G10,1)+0.0001*LARGE('Results and Rankings'!$C10:$G10,2)+0.0000001*LARGE('Results and Rankings'!$C10:$G10,3)+1E-11*LARGE('Results and Rankings'!$C10:$G10,4)+1E-14*LARGE('Results and Rankings'!$C10:$G10,5))) | I10: =IF('Results and Rankings'!$A10="","",_xlfn.RANK.EQ('Results and Rankings'!$H10,'Results and Rankings'!$H$3:$H$202)) | J10: {=IF('Results and Rankings'!$A10="","",XLOOKUP('Results and Rankings'!$A10,'Core Values Input'!$A$2:$A$201,'Core Values Input'!$V$2:$V$201,NumberOfTeams+1,0,))} | K10: {=IF('Results and Rankings'!$A10="","",XLOOKUP('Results and Rankings'!$A10,'Innovation Project Input'!$A$2:$A$201,'Innovation Project Input'!$N$2:$N$201,NumberOfTeams+1,0,))} | L10: {=IF('Results and Rankings'!$A10="","",XLOOKUP('Results and Rankings'!$A10,'Robot Design Input'!$A$2:$A$201,'Robot Design Input'!$N$2:$N$201,NumberOfTeams+1,0,))} | M10: =IF('Results and Rankings'!$A10="","",IF('Results and Rankings'!$J10="",NumberOfTeams+1,'Results and Rankings'!$J10) + IF('Results and Rankings'!$K10="",NumberOfTeams+1,'Results and Rankings'!$K10) + IF('Results and Rankings'!$L10="",NumberOfTeams+1,'Results and Rankings'!$L10) + 'Results and Rankings'!$I10) | N10: =IF('Results and Rankings'!$A10="","",IF(M10,RANK(M10,M$3:M$202,1)-COUNTIF(M$3:M$202,0),NumberOfTeams+1)) | O10: {=XLOOKUP('Results and Rankings'!$A10,'Core Values Input'!$A$2:$A$201,'Core Values Input'!$W$2:$W$201,0,0,)} -> #VALUE! | P10: {=XLOOKUP('Results and Rankings'!$A10,'Core Values Input'!$A$2:$A$201,'Core Values Input'!$X$2:$X$201,0,0,)} -> #VALUE! | Q10: {=XLOOKUP('Results and Rankings'!$A10,'Core Values Input'!$A$2:$A$201,'Core Values Input'!$Y$2:$Y$201,0,0,)} -> #VALUE! | U10: {=XLOOKUP('Results and Rankings'!$A10,'Core Values Input'!$A$2:$A$201,'Core Values Input'!$U$2:$U$201,0,0,)} -> #VALUE! | V10: {=XLOOKUP('Results and Rankings'!$A10,'Innovation Project Input'!$A$2:$A$201,'Innovation Project Input'!$M$2:$M$201,0,0,)} -> #VALUE! | W10: {=XLOOKUP('Results and Rankings'!$A10,'Robot Design Input'!$A$2:$A$201,'Robot Design Input'!$M$2:$M$201,0,0,)} -> #VALUE! | X10: =IF(ISERR(GEOMEAN('Results and Rankings'!$H10,'Results and Rankings'!$U10,'Results and Rankings'!$V10,'Results and Rankings'!$W10)),0,GEOMEAN('Results and Rankings'!$H10,'Results and Rankings'!$U10,'Results and Rankings'!$V10,'Results and Rankings'!$W10)) -> 0 | Y10: =IF(X10,_xlfn.RANK.EQ(X10,X$3:X$110,0),NumberOfTeams) -> 0
A11: {=XLOOKUP(9,'Team and Program Information'!$B$3:$B$202,'Team and Program Information'!$C$3:$C$202,"ERROR",0)} | B11: {=XLOOKUP('Results and Rankings'!$A11,'Team and Program Information'!$C$3:$C$202,'Team and Program Information'!$D$3:$D$202,"",0,)} -> #VALUE! | C11: {=IF('Results and Rankings'!$A11="","",XLOOKUP('Results and Rankings'!$A11,'Robot Game Scores'!$B$2:$B$201,'Robot Game Scores'!$D$2:$D$201,0,0,))} | D11: {=IF('Results and Rankings'!$A11="","",XLOOKUP('Results and Rankings'!$A11,'Robot Game Scores'!$B$2:$B$201,'Robot Game Scores'!$E$2:$E$201,0,0,))} | E11: {=IF('Results and Rankings'!$A11="","",XLOOKUP('Results and Rankings'!$A11,'Robot Game Scores'!$B$2:$B$201,'Robot Game Scores'!$F$2:$F$201,0,0,))} | F11: {=IF('Results and Rankings'!$A11="","",XLOOKUP('Results and Rankings'!$A11,'Robot Game Scores'!$B$2:$B$201,'Robot Game Scores'!$G$2:$G$201,0,0,))} | G11: {=IF('Results and Rankings'!$A11="","",XLOOKUP('Results and Rankings'!$A11,'Robot Game Scores'!$B$2:$B$201,'Robot Game Scores'!$H$2:$H$201,0,0,))} | H11: =IF('Results and Rankings'!$A11="","",IF(ISNA(LARGE('Results and Rankings'!$C11:$G11,1)+0.0001*LARGE('Results and Rankings'!$C11:$G11,2)+0.0000001*LARGE('Results and Rankings'!$C11:$G11,3)+1E-11*LARGE('Results and Rankings'!$C11:$G11,4)+1E-14*LARGE('Results and Rankings'!$C11:$G11,5)),0,LARGE('Results and Rankings'!$C11:$G11,1)+0.0001*LARGE('Results and Rankings'!$C11:$G11,2)+0.0000001*LARGE('Results and Rankings'!$C11:$G11,3)+1E-11*LARGE('Results and Rankings'!$C11:$G11,4)+1E-14*LARGE('Results and Rankings'!$C11:$G11,5))) | I11: =IF('Results and Rankings'!$A11="","",_xlfn.RANK.EQ('Results and Rankings'!$H11,'Results and Rankings'!$H$3:$H$202)) | J11: {=IF('Results and Rankings'!$A11="","",XLOOKUP('Results and Rankings'!$A11,'Core Values Input'!$A$2:$A$201,'Core Values Input'!$V$2:$V$201,NumberOfTeams+1,0,))} | K11: {=IF('Results and Rankings'!$A11="","",XLOOKUP('Results and Rankings'!$A11,'Innovation Project Input'!$A$2:$A$201,'Innovation Project Input'!$N$2:$N$201,NumberOfTeams+1,0,))} | L11: {=IF('Results and Rankings'!$A11="","",XLOOKUP('Results and Rankings'!$A11,'Robot Design Input'!$A$2:$A$201,'Robot Design Input'!$N$2:$N$201,NumberOfTeams+1,0,))} | M11: =IF('Results and Rankings'!$A11="","",IF('Results and Rankings'!$J11="",NumberOfTeams+1,'Results and Rankings'!$J11) + IF('Results and Rankings'!$K11="",NumberOfTeams+1,'Results and Rankings'!$K11) + IF('Results and Rankings'!$L11="",NumberOfTeams+1,'Results and Rankings'!$L11) + 'Results and Rankings'!$I11) | N11: =IF('Results and Rankings'!$A11="","",IF(M11,RANK(M11,M$3:M$202,1)-COUNTIF(M$3:M$202,0),NumberOfTeams+1)) | O11: {=XLOOKUP('Results and Rankings'!$A11,'Core Values Input'!$A$2:$A$201,'Core Values Input'!$W$2:$W$201,0,0,)} -> #VALUE! | P11: {=XLOOKUP('Results and Rankings'!$A11,'Core Values Input'!$A$2:$A$201,'Core Values Input'!$X$2:$X$201,0,0,)} -> #VALUE! | Q11: {=XLOOKUP('Results and Rankings'!$A11,'Core Values Input'!$A$2:$A$201,'Core Values Input'!$Y$2:$Y$201,0,0,)} -> #VALUE! | U11: {=XLOOKUP('Results and Rankings'!$A11,'Core Values Input'!$A$2:$A$201,'Core Values Input'!$U$2:$U$201,0,0,)} -> #VALUE! | V11: {=XLOOKUP('Results and Rankings'!$A11,'Innovation Project Input'!$A$2:$A$201,'Innovation Project Input'!$M$2:$M$201,0,0,)} -> #VALUE! | W11: {=XLOOKUP('Results and Rankings'!$A11,'Robot Design Input'!$A$2:$A$201,'Robot Design Input'!$M$2:$M$201,0,0,)} -> #VALUE! | X11: =IF(ISERR(GEOMEAN('Results and Rankings'!$H11,'Results and Rankings'!$U11,'Results and Rankings'!$V11,'Results and Rankings'!$W11)),0,GEOMEAN('Results and Rankings'!$H11,'Results and Rankings'!$U11,'Results and Rankings'!$V11,'Results and Rankings'!$W11)) -> 0 | Y11: =IF(X11,_xlfn.RANK.EQ(X11,X$3:X$110,0),NumberOfTeams) -> 0
A12: {=XLOOKUP(10,'Team and Program Information'!$B$3:$B$202,'Team and Program Information'!$C$3:$C$202,"ERROR",0)} | B12: {=XLOOKUP('Results and Rankings'!$A12,'Team and Program Information'!$C$3:$C$202,'Team and Program Information'!$D$3:$D$202,"",0,)} -> #VALUE! | C12: {=IF('Results and Rankings'!$A12="","",XLOOKUP('Results and Rankings'!$A12,'Robot Game Scores'!$B$2:$B$201,'Robot Game Scores'!$D$2:$D$201,0,0,))} | D12: {=IF('Results and Rankings'!$A12="","",XLOOKUP('Results and Rankings'!$A12,'Robot Game Scores'!$B$2:$B$201,'Robot Game Scores'!$E$2:$E$201,0,0,))} | E12: {=IF('Results and Rankings'!$A12="","",XLOOKUP('Results and Rankings'!$A12,'Robot Game Scores'!$B$2:$B$201,'Robot Game Scores'!$F$2:$F$201,0,0,))} | F12: {=IF('Results and Rankings'!$A12="","",XLOOKUP('Results and Rankings'!$A12,'Robot Game Scores'!$B$2:$B$201,'Robot Game Scores'!$G$2:$G$201,0,0,))} | G12: {=IF('Results and Rankings'!$A12="","",XLOOKUP('Results and Rankings'!$A12,'Robot Game Scores'!$B$2:$B$201,'Robot Game Scores'!$H$2:$H$201,0,0,))} | H12: =IF('Results and Rankings'!$A12="","",IF(ISNA(LARGE('Results and Rankings'!$C12:$G12,1)+0.0001*LARGE('Results and Rankings'!$C12:$G12,2)+0.0000001*LARGE('Results and Rankings'!$C12:$G12,3)+1E-11*LARGE('Results and Rankings'!$C12:$G12,4)+1E-14*LARGE('Results and Rankings'!$C12:$G12,5)),0,LARGE('Results and Rankings'!$C12:$G12,1)+0.0001*LARGE('Results and Rankings'!$C12:$G12,2)+0.0000001*LARGE('Results and Rankings'!$C12:$G12,3)+1E-11*LARGE('Results and Rankings'!$C12:$G12,4)+1E-14*LARGE('Results and Rankings'!$C12:$G12,5))) | I12: =IF('Results and Rankings'!$A12="","",_xlfn.RANK.EQ('Results and Rankings'!$H12,'Results and Rankings'!$H$3:$H$202)) | J12: {=IF('Results and Rankings'!$A12="","",XLOOKUP('Results and Rankings'!$A12,'Core Values Input'!$A$2:$A$201,'Core Values Input'!$V$2:$V$201,NumberOfTeams+1,0,))} | K12: {=IF('Results and Rankings'!$A12="","",XLOOKUP('Results and Rankings'!$A12,'Innovation Project Input'!$A$2:$A$201,'Innovation Project Input'!$N$2:$N$201,NumberOfTeams+1,0,))} | L12: {=IF('Results and Rankings'!$A12="","",XLOOKUP('Results and Rankings'!$A12,'Robot Design Input'!$A$2:$A$201,'Robot Design Input'!$N$2:$N$201,NumberOfTeams+1,0,))} | M12: =IF('Results and Rankings'!$A12="","",IF('Results and Rankings'!$J12="",NumberOfTeams+1,'Results and Rankings'!$J12) + IF('Results and Rankings'!$K12="",NumberOfTeams+1,'Results and Rankings'!$K12) + IF('Results and Rankings'!$L12="",NumberOfTeams+1,'Results and Rankings'!$L12) + 'Results and Rankings'!$I12) | N12: =IF('Results and Rankings'!$A12="","",IF(M12,RANK(M12,M$3:M$202,1)-COUNTIF(M$3:M$202,0),NumberOfTeams+1)) | O12: {=XLOOKUP('Results and Rankings'!$A12,'Core Values Input'!$A$2:$A$201,'Core Values Input'!$W$2:$W$201,0,0,)} -> #VALUE! | P12: {=XLOOKUP('Results and Rankings'!$A12,'Core Values Input'!$A$2:$A$201,'Core Values Input'!$X$2:$X$201,0,0,)} -> #VALUE! | Q12: {=XLOOKUP('Results and Rankings'!$A12,'Core Values Input'!$A$2:$A$201,'Core Values Input'!$Y$2:$Y$201,0,0,)} -> #VALUE! | U12: {=XLOOKUP('Results and Rankings'!$A12,'Core Values Input'!$A$2:$A$201,'Core Values Input'!$U$2:$U$201,0,0,)} -> #VALUE! | V12: {=XLOOKUP('Results and Rankings'!$A12,'Innovation Project Input'!$A$2:$A$201,'Innovation Project Input'!$M$2:$M$201,0,0,)} -> #VALUE! | W12: {=XLOOKUP('Results and Rankings'!$A12,'Robot Design Input'!$A$2:$A$201,'Robot Design Input'!$M$2:$M$201,0,0,)} -> #VALUE! | X12: =IF(ISERR(GEOMEAN('Results and Rankings'!$H12,'Results and Rankings'!$U12,'Results and Rankings'!$V12,'Results and Rankings'!$W12)),0,GEOMEAN('Results and Rankings'!$H12,'Results and Rankings'!$U12,'Results and Rankings'!$V12,'Results and Rankings'!$W12)) -> 0 | Y12: =IF(X12,_xlfn.RANK.EQ(X12,X$3:X$110,0),NumberOfTeams) -> 0
A13: {=XLOOKUP(11,'Team and Program Information'!$B$3:$B$202,'Team and Program Information'!$C$3:$C$202,"ERROR",0)} | B13: {=XLOOKUP('Results and Rankings'!$A13,'Team and Program Information'!$C$3:$C$202,'Team and Program Information'!$D$3:$D$202,"",0,)} -> #VALUE! | C13: {=IF('Results and Rankings'!$A13="","",XLOOKUP('Results and Rankings'!$A13,'Robot Game Scores'!$B$2:$B$201,'Robot Game Scores'!$D$2:$D$201,0,0,))} | D13: {=IF('Results and Rankings'!$A13="","",XLOOKUP('Results and Rankings'!$A13,'Robot Game Scores'!$B$2:$B$201,'Robot Game Scores'!$E$2:$E$201,0,0,))} | E13: {=IF('Results and Rankings'!$A13="","",XLOOKUP('Results and Rankings'!$A13,'Robot Game Scores'!$B$2:$B$201,'Robot Game Scores'!$F$2:$F$201,0,0,))} | F13: {=IF('Results and Rankings'!$A13="","",XLOOKUP('Results and Rankings'!$A13,'Robot Game Scores'!$B$2:$B$201,'Robot Game Scores'!$G$2:$G$201,0,0,))} | G13: {=IF('Results and Rankings'!$A13="","",XLOOKUP('Results and Rankings'!$A13,'Robot Game Scores'!$B$2:$B$201,'Robot Game Scores'!$H$2:$H$201,0,0,))} | H13: =IF('Results and Rankings'!$A13="","",IF(ISNA(LARGE('Results and Rankings'!$C13:$G13,1)+0.0001*LARGE('Results and Rankings'!$C13:$G13,2)+0.0000001*LARGE('Results and Rankings'!$C13:$G13,3)+1E-11*LARGE('Results and Rankings'!$C13:$G13,4)+1E-14*LARGE('Results and Rankings'!$C13:$G13,5)),0,LARGE('Results and Rankings'!$C13:$G13,1)+0.0001*LARGE('Results and Rankings'!$C13:$G13,2)+0.0000001*LARGE('Results and Rankings'!$C13:$G13,3)+1E-11*LARGE('Results and Rankings'!$C13:$G13,4)+1E-14*LARGE('Results and Rankings'!$C13:$G13,5))) | I13: =IF('Results and Rankings'!$A13="","",_xlfn.RANK.EQ('Results and Rankings'!$H13,'Results and Rankings'!$H$3:$H$202)) | J13: {=IF('Results and Rankings'!$A13="","",XLOOKUP('Results and Rankings'!$A13,'Core Values Input'!$A$2:$A$201,'Core Values Input'!$V$2:$V$201,NumberOfTeams+1,0,))} | K13: {=IF('Results and Rankings'!$A13="","",XLOOKUP('Results and Rankings'!$A13,'Innovation Project Input'!$A$2:$A$201,'Innovation Project Input'!$N$2:$N$201,NumberOfTeams+1,0,))} | L13: {=IF('Results and Rankings'!$A13="","",XLOOKUP('Results and Rankings'!$A13,'Robot Design Input'!$A$2:$A$201,'Robot Design Input'!$N$2:$N$201,NumberOfTeams+1,0,))} | M13: =IF('Results and Rankings'!$A13="","",IF('Results and Rankings'!$J13="",NumberOfTeams+1,'Results and Rankings'!$J13) + IF('Results and Rankings'!$K13="",NumberOfTeams+1,'Results and Rankings'!$K13) + IF('Results and Rankings'!$L13="",NumberOfTeams+1,'Results and Rankings'!$L13) + 'Results and Rankings'!$I13) | N13: =IF('Results and Rankings'!$A13="","",IF(M13,RANK(M13,M$3:M$202,1)-COUNTIF(M$3:M$202,0),NumberOfTeams+1)) | O13: {=XLOOKUP('Results and Rankings'!$A13,'Core Values Input'!$A$2:$A$201,'Core Values Input'!$W$2:$W$201,0,0,)} -> #VALUE! | P13: {=XLOOKUP('Results and Rankings'!$A13,'Core Values Input'!$A$2:$A$201,'Core Values Input'!$X$2:$X$201,0,0,)} -> #VALUE! | Q13: {=XLOOKUP('Results and Rankings'!$A13,'Core Values Input'!$A$2:$A$201,'Core Values Input'!$Y$2:$Y$201,0,0,)} -> #VALUE! | U13: {=XLOOKUP('Results and Rankings'!$A13,'Core Values Input'!$A$2:$A$201,'Core Values Input'!$U$2:$U$201,0,0,)} -> #VALUE! | V13: {=XLOOKUP('Results and Rankings'!$A13,'Innovation Project Input'!$A$2:$A$201,'Innovation Project Input'!$M$2:$M$201,0,0,)} -> #VALUE! | W13: {=XLOOKUP('Results and Rankings'!$A13,'Robot Design Input'!$A$2:$A$201,'Robot Design Input'!$M$2:$M$201,0,0,)} -> #VALUE! | X13: =IF(ISERR(GEOMEAN('Results and Rankings'!$H13,'Results and Rankings'!$U13,'Results and Rankings'!$V13,'Results and Rankings'!$W13)),0,GEOMEAN('Results and Rankings'!$H13,'Results and Rankings'!$U13,'Results and Rankings'!$V13,'Results and Rankings'!$W13)) -> 0 | Y13: =IF(X13,_xlfn.RANK.EQ(X13,X$3:X$110,0),NumberOfTeams) -> 0
A14: {=XLOOKUP(12,'Team and Program Information'!$B$3:$B$202,'Team and Program Information'!$C$3:$C$202,"ERROR",0)} | B14: {=XLOOKUP('Results and Rankings'!$A14,'Team and Program Information'!$C$3:$C$202,'Team and Program Information'!$D$3:$D$202,"",0,)} -> #VALUE! | C14: {=IF('Results and Rankings'!$A14="","",XLOOKUP('Results and Rankings'!$A14,'Robot Game Scores'!$B$2:$B$201,'Robot Game Scores'!$D$2:$D$201,0,0,))} | D14: {=IF('Results and Rankings'!$A14="","",XLOOKUP('Results and Rankings'!$A14,'Robot Game Scores'!$B$2:$B$201,'Robot Game Scores'!$E$2:$E$201,0,0,))} | E14: {=IF('Results and Rankings'!$A14="","",XLOOKUP('Results and Rankings'!$A14,'Robot Game Scores'!$B$2:$B$201,'Robot Game Scores'!$F$2:$F$201,0,0,))} | F14: {=IF('Results and Rankings'!$A14="","",XLOOKUP('Results and Rankings'!$A14,'Robot Game Scores'!$B$2:$B$201,'Robot Game Scores'!$G$2:$G$201,0,0,))} | G14: {=IF('Results and Rankings'!$A14="","",XLOOKUP('Results and Rankings'!$A14,'Robot Game Scores'!$B$2:$B$201,'Robot Game Scores'!$H$2:$H$201,0,0,))} | H14: =IF('Results and Rankings'!$A14="","",IF(ISNA(LARGE('Results and Rankings'!$C14:$G14,1)+0.0001*LARGE('Results and Rankings'!$C14:$G14,2)+0.0000001*LARGE('Results and Rankings'!$C14:$G14,3)+1E-11*LARGE('Results and Rankings'!$C14:$G14,4)+1E-14*LARGE('Results and Rankings'!$C14:$G14,5)),0,LARGE('Results and Rankings'!$C14:$G14,1)+0.0001*LARGE('Results and Rankings'!$C14:$G14,2)+0.0000001*LARGE('Results and Rankings'!$C14:$G14,3)+1E-11*LARGE('Results and Rankings'!$C14:$G14,4)+1E-14*LARGE('Results and Rankings'!$C14:$G14,5))) | I14: =IF('Results and Rankings'!$A14="","",_xlfn.RANK.EQ('Results and Rankings'!$H14,'Results and Rankings'!$H$3:$H$202)) | J14: {=IF('Results and Rankings'!$A14="","",XLOOKUP('Results and Rankings'!$A14,'Core Values Input'!$A$2:$A$201,'Core Values Input'!$V$2:$V$201,NumberOfTeams+1,0,))} | K14: {=IF('Results and Rankings'!$A14="","",XLOOKUP('Results and Rankings'!$A14,'Innovation Project Input'!$A$2:$A$201,'Innovation Project Input'!$N$2:$N$201,NumberOfTeams+1,0,))} | L14: {=IF('Results and Rankings'!$A14="","",XLOOKUP('Results and Rankings'!$A14,'Robot Design Input'!$A$2:$A$201,'Robot Design Input'!$N$2:$N$201,NumberOfTeams+1,0,))} | M14: =IF('Results and Rankings'!$A14="","",IF('Results and Rankings'!$J14="",NumberOfTeams+1,'Results and Rankings'!$J14) + IF('Results and Rankings'!$K14="",NumberOfTeams+1,'Results and Rankings'!$K14) + IF('Results and Rankings'!$L14="",NumberOfTeams+1,'Results and Rankings'!$L14) + 'Results and Rankings'!$I14) | N14: =IF('Results and Rankings'!$A14="","",IF(M14,RANK(M14,M$3:M$202,1)-COUNTIF(M$3:M$202,0),NumberOfTeams+1)) | O14: {=XLOOKUP('Results and Rankings'!$A14,'Core Values Input'!$A$2:$A$201,'Core Values Input'!$W$2:$W$201,0,0,)} -> #VALUE! | P14: {=XLOOKUP('Results and Rankings'!$A14,'Core Values Input'!$A$2:$A$201,'Core Values Input'!$X$2:$X$201,0,0,)} -> #VALUE! | Q14: {=XLOOKUP('Results and Rankings'!$A14,'Core Values Input'!$A$2:$A$201,'Core Values Input'!$Y$2:$Y$201,0,0,)} -> #VALUE! | U14: {=XLOOKUP('Results and Rankings'!$A14,'Core Values Input'!$A$2:$A$201,'Core Values Input'!$U$2:$U$201,0,0,)} -> #VALUE! | V14: {=XLOOKUP('Results and Rankings'!$A14,'Innovation Project Input'!$A$2:$A$201,'Innovation Project Input'!$M$2:$M$201,0,0,)} -> #VALUE! | W14: {=XLOOKUP('Results and Rankings'!$A14,'Robot Design Input'!$A$2:$A$201,'Robot Design Input'!$M$2:$M$201,0,0,)} -> #VALUE! | X14: =IF(ISERR(GEOMEAN('Results and Rankings'!$H14,'Results and Rankings'!$U14,'Results and Rankings'!$V14,'Results and Rankings'!$W14)),0,GEOMEAN('Results and Rankings'!$H14,'Results and Rankings'!$U14,'Results and Rankings'!$V14,'Results and Rankings'!$W14)) -> 0 | Y14: =IF(X14,_xlfn.RANK.EQ(X14,X$3:X$110,0),NumberOfTeams) -> 0
A15: {=XLOOKUP(13,'Team and Program Information'!$B$3:$B$202,'Team and Program Information'!$C$3:$C$202,"ERROR",0)} | B15: {=XLOOKUP('Results and Rankings'!$A15,'Team and Program Information'!$C$3:$C$202,'Team and Program Information'!$D$3:$D$202,"",0,)} -> #VALUE! | C15: {=IF('Results and Rankings'!$A15="","",XLOOKUP('Results and Rankings'!$A15,'Robot Game Scores'!$B$2:$B$201,'Robot Game Scores'!$D$2:$D$201,0,0,))} | D15: {=IF('Results and Rankings'!$A15="","",XLOOKUP('Results and Rankings'!$A15,'Robot Game Scores'!$B$2:$B$201,'Robot Game Scores'!$E$2:$E$201,0,0,))} | E15: {=IF('Results and Rankings'!$A15="","",XLOOKUP('Results and Rankings'!$A15,'Robot Game Scores'!$B$2:$B$201,'Robot Game Scores'!$F$2:$F$201,0,0,))} | F15: {=IF('Results and Rankings'!$A15="","",XLOOKUP('Results and Rankings'!$A15,'Robot Game Scores'!$B$2:$B$201,'Robot Game Scores'!$G$2:$G$201,0,0,))} | G15: {=IF('Results and Rankings'!$A15="","",XLOOKUP('Results and Rankings'!$A15,'Robot Game Scores'!$B$2:$B$201,'Robot Game Scores'!$H$2:$H$201,0,0,))} | H15: =IF('Results and Rankings'!$A15="","",IF(ISNA(LARGE('Results and Rankings'!$C15:$G15,1)+0.0001*LARGE('Results and Rankings'!$C15:$G15,2)+0.0000001*LARGE('Results and Rankings'!$C15:$G15,3)+1E-11*LARGE('Results and Rankings'!$C15:$G15,4)+1E-14*LARGE('Results and Rankings'!$C15:$G15,5)),0,LARGE('Results and Rankings'!$C15:$G15,1)+0.0001*LARGE('Results and Rankings'!$C15:$G15,2)+0.0000001*LARGE('Results and Rankings'!$C15:$G15,3)+1E-11*LARGE('Results and Rankings'!$C15:$G15,4)+1E-14*LARGE('Results and Rankings'!$C15:$G15,5))) | I15: =IF('Results and Rankings'!$A15="","",_xlfn.RANK.EQ('Results and Rankings'!$H15,'Results and Rankings'!$H$3:$H$202)) | J15: {=IF('Results and Rankings'!$A15="","",XLOOKUP('Results and Rankings'!$A15,'Core Values Input'!$A$2:$A$201,'Core Values Input'!$V$2:$V$201,NumberOfTeams+1,0,))} | K15: {=IF('Results and Rankings'!$A15="","",XLOOKUP('Results and Rankings'!$A15,'Innovation Project Input'!$A$2:$A$201,'Innovation Project Input'!$N$2:$N$201,NumberOfTeams+1,0,))} | L15: {=IF('Results and Rankings'!$A15="","",XLOOKUP('Results and Rankings'!$A15,'Robot Design Input'!$A$2:$A$201,'Robot Design Input'!$N$2:$N$201,NumberOfTeams+1,0,))} | M15: =IF('Results and Rankings'!$A15="","",IF('Results and Rankings'!$J15="",NumberOfTeams+1,'Results and Rankings'!$J15) + IF('Results and Rankings'!$K15="",NumberOfTeams+1,'Results and Rankings'!$K15) + IF('Results and Rankings'!$L15="",NumberOfTeams+1,'Results and Rankings'!$L15) + 'Results and Rankings'!$I15) | N15: =IF('Results and Rankings'!$A15="","",IF(M15,RANK(M15,M$3:M$202,1)-COUNTIF(M$3:M$202,0),NumberOfTeams+1)) | O15: {=XLOOKUP('Results and Rankings'!$A15,'Core Values Input'!$A$2:$A$201,'Core Values Input'!$W$2:$W$201,0,0,)} -> #VALUE! | P15: {=XLOOKUP('Results and Rankings'!$A15,'Core Values Input'!$A$2:$A$201,'Core Values Input'!$X$2:$X$201,0,0,)} -> #VALUE! | Q15: {=XLOOKUP('Results and Rankings'!$A15,'Core Values Input'!$A$2:$A$201,'Core Values Input'!$Y$2:$Y$201,0,0,)} -> #VALUE! | U15: {=XLOOKUP('Results and Rankings'!$A15,'Core Values Input'!$A$2:$A$201,'Core Values Input'!$U$2:$U$201,0,0,)} -> #VALUE! | V15: {=XLOOKUP('Results and Rankings'!$A15,'Innovation Project Input'!$A$2:$A$201,'Innovation Project Input'!$M$2:$M$201,0,0,)} -> #VALUE! | W15: {=XLOOKUP('Results and Rankings'!$A15,'Robot Design Input'!$A$2:$A$201,'Robot Design Input'!$M$2:$M$201,0,0,)} -> #VALUE! | X15: =IF(ISERR(GEOMEAN('Results and Rankings'!$H15,'Results and Rankings'!$U15,'Results and Rankings'!$V15,'Results and Rankings'!$W15)),0,GEOMEAN('Results and Rankings'!$H15,'Results and Rankings'!$U15,'Results and Rankings'!$V15,'Results and Rankings'!$W15)) -> 0 | Y15: =IF(X15,_xlfn.RANK.EQ(X15,X$3:X$110,0),NumberOfTeams) -> 0
A16: {=XLOOKUP(14,'Team and Program Information'!$B$3:$B$202,'Team and Program Information'!$C$3:$C$202,"ERROR",0)} | B16: {=XLOOKUP('Results and Rankings'!$A16,'Team and Program Information'!$C$3:$C$202,'Team and Program Information'!$D$3:$D$202,"",0,)} -> #VALUE! | C16: {=IF('Results and Rankings'!$A16="","",XLOOKUP('Results and Rankings'!$A16,'Robot Game Scores'!$B$2:$B$201,'Robot Game Scores'!$D$2:$D$201,0,0,))} | D16: {=IF('Results and Rankings'!$A16="","",XLOOKUP('Results and Rankings'!$A16,'Robot Game Scores'!$B$2:$B$201,'Robot Game Scores'!$E$2:$E$201,0,0,))} | E16: {=IF('Results and Rankings'!$A16="","",XLOOKUP('Results and Rankings'!$A16,'Robot Game Scores'!$B$2:$B$201,'Robot Game Scores'!$F$2:$F$201,0,0,))} | F16: {=IF('Results and Rankings'!$A16="","",XLOOKUP('Results and Rankings'!$A16,'Robot Game Scores'!$B$2:$B$201,'Robot Game Scores'!$G$2:$G$201,0,0,))} | G16: {=IF('Results and Rankings'!$A16="","",XLOOKUP('Results and Rankings'!$A16,'Robot Game Scores'!$B$2:$B$201,'Robot Game Scores'!$H$2:$H$201,0,0,))} | H16: =IF('Results and Rankings'!$A16="","",IF(ISNA(LARGE('Results and Rankings'!$C16:$G16,1)+0.0001*LARGE('Results and Rankings'!$C16:$G16,2)+0.0000001*LARGE('Results and Rankings'!$C16:$G16,3)+1E-11*LARGE('Results and Rankings'!$C16:$G16,4)+1E-14*LARGE('Results and Rankings'!$C16:$G16,5)),0,LARGE('Results and Rankings'!$C16:$G16,1)+0.0001*LARGE('Results and Rankings'!$C16:$G16,2)+0.0000001*LARGE('Results and Rankings'!$C16:$G16,3)+1E-11*LARGE('Results and Rankings'!$C16:$G16,4)+1E-14*LARGE('Results and Rankings'!$C16:$G16,5))) | I16: =IF('Results and Rankings'!$A16="","",_xlfn.RANK.EQ('Results and Rankings'!$H16,'Results and Rankings'!$H$3:$H$202)) | J16: {=IF('Results and Rankings'!$A16="","",XLOOKUP('Results and Rankings'!$A16,'Core Values Input'!$A$2:$A$201,'Core Values Input'!$V$2:$V$201,NumberOfTeams+1,0,))} | K16: {=IF('Results and Rankings'!$A16="","",XLOOKUP('Results and Rankings'!$A16,'Innovation Project Input'!$A$2:$A$201,'Innovation Project Input'!$N$2:$N$201,NumberOfTeams+1,0,))} | L16: {=IF('Results and Rankings'!$A16="","",XLOOKUP('Results and Rankings'!$A16,'Robot Design Input'!$A$2:$A$201,'Robot Design Input'!$N$2:$N$201,NumberOfTeams+1,0,))} | M16: =IF('Results and Rankings'!$A16="","",IF('Results and Rankings'!$J16="",NumberOfTeams+1,'Results and Rankings'!$J16) + IF('Results and Rankings'!$K16="",NumberOfTeams+1,'Results and Rankings'!$K16) + IF('Results and Rankings'!$L16="",NumberOfTeams+1,'Results and Rankings'!$L16) + 'Results and Rankings'!$I16) | N16: =IF('Results and Rankings'!$A16="","",IF(M16,RANK(M16,M$3:M$202,1)-COUNTIF(M$3:M$202,0),NumberOfTeams+1)) | O16: {=XLOOKUP('Results and Rankings'!$A16,'Core Values Input'!$A$2:$A$201,'Core Values Input'!$W$2:$W$201,0,0,)} -> #VALUE! | P16: {=XLOOKUP('Results and Rankings'!$A16,'Core Values Input'!$A$2:$A$201,'Core Values Input'!$X$2:$X$201,0,0,)} -> #VALUE! | Q16: {=XLOOKUP('Results and Rankings'!$A16,'Core Values Input'!$A$2:$A$201,'Core Values Input'!$Y$2:$Y$201,0,0,)} -> #VALUE! | U16: {=XLOOKUP('Results and Rankings'!$A16,'Core Values Input'!$A$2:$A$201,'Core Values Input'!$U$2:$U$201,0,0,)} -> #VALUE! | V16: {=XLOOKUP('Results and Rankings'!$A16,'Innovation Project Input'!$A$2:$A$201,'Innovation Project Input'!$M$2:$M$201,0,0,)} -> #VALUE! | W16: {=XLOOKUP('Results and Rankings'!$A16,'Robot Design Input'!$A$2:$A$201,'Robot Design Input'!$M$2:$M$201,0,0,)} -> #VALUE! | X16: =IF(ISERR(GEOMEAN('Results and Rankings'!$H16,'Results and Rankings'!$U16,'Results and Rankings'!$V16,'Results and Rankings'!$W16)),0,GEOMEAN('Results and Rankings'!$H16,'Results and Rankings'!$U16,'Results and Rankings'!$V16,'Results and Rankings'!$W16)) -> 0 | Y16: =IF(X16,_xlfn.RANK.EQ(X16,X$3:X$110,0),NumberOfTeams) -> 0
A17: {=XLOOKUP(15,'Team and Program Information'!$B$3:$B$202,'Team and Program Information'!$C$3:$C$202,"ERROR",0)} | B17: {=XLOOKUP('Results and Rankings'!$A17,'Team and Program Information'!$C$3:$C$202,'Team and Program Information'!$D$3:$D$202,"",0,)} -> #VALUE! | C17: {=IF('Results and Rankings'!$A17="","",XLOOKUP('Results and Rankings'!$A17,'Robot Game Scores'!$B$2:$B$201,'Robot Game Scores'!$D$2:$D$201,0,0,))} | D17: {=IF('Results and Rankings'!$A17="","",XLOOKUP('Results and Rankings'!$A17,'Robot Game Scores'!$B$2:$B$201,'Robot Game Scores'!$E$2:$E$201,0,0,))} | E17: {=IF('Results and Rankings'!$A17="","",XLOOKUP('Results and Rankings'!$A17,'Robot Game Scores'!$B$2:$B$201,'Robot Game Scores'!$F$2:$F$201,0,0,))} | F17: {=IF('Results and Rankings'!$A17="","",XLOOKUP('Results and Rankings'!$A17,'Robot Game Scores'!$B$2:$B$201,'Robot Game Scores'!$G$2:$G$201,0,0,))} | G17: {=IF('Results and Rankings'!$A17="","",XLOOKUP('Results and Rankings'!$A17,'Robot Game Scores'!$B$2:$B$201,'Robot Game Scores'!$H$2:$H$201,0,0,))} | H17: =IF('Results and Rankings'!$A17="","",IF(ISNA(LARGE('Results and Rankings'!$C17:$G17,1)+0.0001*LARGE('Results and Rankings'!$C17:$G17,2)+0.0000001*LARGE('Results and Rankings'!$C17:$G17,3)+1E-11*LARGE('Results and Rankings'!$C17:$G17,4)+1E-14*LARGE('Results and Rankings'!$C17:$G17,5)),0,LARGE('Results and Rankings'!$C17:$G17,1)+0.0001*LARGE('Results and Rankings'!$C17:$G17,2)+0.0000001*LARGE('Results and Rankings'!$C17:$G17,3)+1E-11*LARGE('Results and Rankings'!$C17:$G17,4)+1E-14*LARGE('Results and Rankings'!$C17:$G17,5))) | I17: =IF('Results and Rankings'!$A17="","",_xlfn.RANK.EQ('Results and Rankings'!$H17,'Results and Rankings'!$H$3:$H$202)) | J17: {=IF('Results and Rankings'!$A17="","",XLOOKUP('Results and Rankings'!$A17,'Core Values Input'!$A$2:$A$201,'Core Values Input'!$V$2:$V$201,NumberOfTeams+1,0,))} | K17: {=IF('Results and Rankings'!$A17="","",XLOOKUP('Results and Rankings'!$A17,'Innovation Project Input'!$A$2:$A$201,'Innovation Project Input'!$N$2:$N$201,NumberOfTeams+1,0,))} | L17: {=IF('Results and Rankings'!$A17="","",XLOOKUP('Results and Rankings'!$A17,'Robot Design Input'!$A$2:$A$201,'Robot Design Input'!$N$2:$N$201,NumberOfTeams+1,0,))} | M17: =IF('Results and Rankings'!$A17="","",IF('Results and Rankings'!$J17="",NumberOfTeams+1,'Results and Rankings'!$J17) + IF('Results and Rankings'!$K17="",NumberOfTeams+1,'Results and Rankings'!$K17) + IF('Results and Rankings'!$L17="",NumberOfTeams+1,'Results and Rankings'!$L17) + 'Results and Rankings'!$I17) | N17: =IF('Results and Rankings'!$A17="","",IF(M17,RANK(M17,M$3:M$202,1)-COUNTIF(M$3:M$202,0),NumberOfTeams+1)) | O17: {=XLOOKUP('Results and Rankings'!$A17,'Core Values Input'!$A$2:$A$201,'Core Values Input'!$W$2:$W$201,0,0,)} -> #VALUE! | P17: {=XLOOKUP('Results and Rankings'!$A17,'Core Values Input'!$A$2:$A$201,'Core Values Input'!$X$2:$X$201,0,0,)} -> #VALUE! | Q17: {=XLOOKUP('Results and Rankings'!$A17,'Core Values Input'!$A$2:$A$201,'Core Values Input'!$Y$2:$Y$201,0,0,)} -> #VALUE! | U17: {=XLOOKUP('Results and Rankings'!$A17,'Core Values Input'!$A$2:$A$201,'Core Values Input'!$U$2:$U$201,0,0,)} -> #VALUE! | V17: {=XLOOKUP('Results and Rankings'!$A17,'Innovation Project Input'!$A$2:$A$201,'Innovation Project Input'!$M$2:$M$201,0,0,)} -> #VALUE! | W17: {=XLOOKUP('Results and Rankings'!$A17,'Robot Design Input'!$A$2:$A$201,'Robot Design Input'!$M$2:$M$201,0,0,)} -> #VALUE! | X17: =IF(ISERR(GEOMEAN('Results and Rankings'!$H17,'Results and Rankings'!$U17,'Results and Rankings'!$V17,'Results and Rankings'!$W17)),0,GEOMEAN('Results and Rankings'!$H17,'Results and Rankings'!$U17,'Results and Rankings'!$V17,'Results and Rankings'!$W17)) -> 0 | Y17: =IF(X17,_xlfn.RANK.EQ(X17,X$3:X$110,0),NumberOfTeams) -> 0
